04/16/2024 00:02:52 - INFO - __main__ - Distributed environment: NO
Num processes: 1
Process index: 0
Local process index: 0
Device: cuda
Mixed precision type: no
Traceback (most recent call last):
  File "C:\Users\nguye\AppData\Local\Programs\Python\Python310\lib\site-packages\diffusers\configuration_utils.py", line 380, in load_config
    config_file = hf_hub_download(
  File "C:\Users\nguye\AppData\Local\Programs\Python\Python310\lib\site-packages\huggingface_hub\utils\_validators.py", line 110, in _inner_fn
    validate_repo_id(arg_value)
  File "C:\Users\nguye\AppData\Local\Programs\Python\Python310\lib\site-packages\huggingface_hub\utils\_validators.py", line 158, in validate_repo_id
    raise HFValidationError(
huggingface_hub.utils._validators.HFValidationError: Repo id must be in the form 'repo_name' or 'namespace/repo_name': 'OFA-Sys/small-stable-diffusion-v0/'. Use `repo_type` argument if needed.
During handling of the above exception, another exception occurred:
Traceback (most recent call last):
  File "E:\CV\Final_Test\FashioneDIFF\train.py", line 324, in <module>
    main()
  File "E:\CV\Final_Test\FashioneDIFF\train.py", line 118, in main
    model, tokenizer = load_models(config)
  File "E:\CV\Final_Test\FashioneDIFF\train.py", line 44, in load_models
    noise_scheduler = DDPMScheduler.from_pretrained(config.pretrained_model_name_or_path, subfolder="scheduler")
  File "C:\Users\nguye\AppData\Local\Programs\Python\Python310\lib\site-packages\huggingface_hub\utils\_validators.py", line 118, in _inner_fn
    return fn(*args, **kwargs)
  File "C:\Users\nguye\AppData\Local\Programs\Python\Python310\lib\site-packages\diffusers\schedulers\scheduling_utils.py", line 143, in from_pretrained
    config, kwargs, commit_hash = cls.load_config(
  File "C:\Users\nguye\AppData\Local\Programs\Python\Python310\lib\site-packages\huggingface_hub\utils\_validators.py", line 118, in _inner_fn
    return fn(*args, **kwargs)
  File "C:\Users\nguye\AppData\Local\Programs\Python\Python310\lib\site-packages\diffusers\configuration_utils.py", line 415, in load_config
    raise EnvironmentError(
OSError: We couldn't connect to 'https://huggingface.co' to load this model, couldn't find it in the cached files and it looks like OFA-Sys/small-stable-diffusion-v0/ is not the path to a directory containing a scheduler_config.json file.
Checkout your internet connection or see how to run the library in offline mode at 'https://huggingface.co/docs/diffusers/installation#offline-mode'.
OFA-Sys/small-stable-diffusion-v0/