
OFA-Sys/small-stable-diffusion-v0
04/16/2024 00:03:45 - INFO - __main__ - Distributed environment: NO
Num processes: 1
Process index: 0
Local process index: 0
Device: cuda
Mixed precision type: no
scheduler/scheduler_config.json: 100%|█████████████████████████████████████████████████████████████████████████| 459/459 [00:00<00:00, 29.4kB/s]
C:\Users\nguye\AppData\Local\Programs\Python\Python310\lib\site-packages\huggingface_hub\file_download.py:149: UserWarning: `huggingface_hub` cache-system uses symlinks by default to efficiently store duplicated files but your machine does not support them in C:\Users\nguye\.cache\huggingface\hub\models--OFA-Sys--small-stable-diffusion-v0. Caching files will still work but in a degraded version that might require more space on your disk. This warning can be disabled by setting the `HF_HUB_DISABLE_SYMLINKS_WARNING` environment variable. For more details, see https://huggingface.co/docs/huggingface_hub/how-to-cache#limitations.
To support symlinks on Windows, you either need to activate Developer Mode or to run Python as an administrator. In order to see activate developer mode, see this article: https://docs.microsoft.com/en-us/windows/apps/get-started/enable-your-device-for-development
  warnings.warn(message)
The config attributes {'predict_epsilon': True} were passed to DDPMScheduler, but are not expected and will be ignored. Please verify your scheduler_config.json configuration file.
{'clip_sample_range', 'clip_sample', 'variance_type', 'timestep_spacing', 'prediction_type', 'rescale_betas_zero_snr', 'steps_offset'} was not found in config. Values will be initialized to default values.
Traceback (most recent call last):
  File "C:\Users\nguye\AppData\Local\Programs\Python\Python310\lib\site-packages\huggingface_hub\utils\_errors.py", line 286, in hf_raise_for_status
    response.raise_for_status()
  File "C:\Users\nguye\AppData\Local\Programs\Python\Python310\lib\site-packages\requests\models.py", line 1021, in raise_for_status
    raise HTTPError(http_error_msg, response=self)
requests.exceptions.HTTPError: 404 Client Error: Not Found for url: https://huggingface.co/OFA-Sys/small-stable-diffusion-v0/resolve/None/tokenizer/tokenizer_config.json
The above exception was the direct cause of the following exception:
Traceback (most recent call last):
  File "C:\Users\nguye\AppData\Local\Programs\Python\Python310\lib\site-packages\transformers\utils\hub.py", line 385, in cached_file
    resolved_file = hf_hub_download(
  File "C:\Users\nguye\AppData\Local\Programs\Python\Python310\lib\site-packages\huggingface_hub\utils\_validators.py", line 118, in _inner_fn
    return fn(*args, **kwargs)
  File "C:\Users\nguye\AppData\Local\Programs\Python\Python310\lib\site-packages\huggingface_hub\file_download.py", line 1238, in hf_hub_download
    metadata = get_hf_file_metadata(
  File "C:\Users\nguye\AppData\Local\Programs\Python\Python310\lib\site-packages\huggingface_hub\utils\_validators.py", line 118, in _inner_fn
    return fn(*args, **kwargs)
  File "C:\Users\nguye\AppData\Local\Programs\Python\Python310\lib\site-packages\huggingface_hub\file_download.py", line 1631, in get_hf_file_metadata
    r = _request_wrapper(
  File "C:\Users\nguye\AppData\Local\Programs\Python\Python310\lib\site-packages\huggingface_hub\file_download.py", line 385, in _request_wrapper
    response = _request_wrapper(
  File "C:\Users\nguye\AppData\Local\Programs\Python\Python310\lib\site-packages\huggingface_hub\file_download.py", line 409, in _request_wrapper
    hf_raise_for_status(response)
  File "C:\Users\nguye\AppData\Local\Programs\Python\Python310\lib\site-packages\huggingface_hub\utils\_errors.py", line 292, in hf_raise_for_status
    raise RevisionNotFoundError(message, response) from e
huggingface_hub.utils._errors.RevisionNotFoundError: 404 Client Error. (Request ID: Root=1-661d5df4-0db2569d4317a0540c169b88;957b7ca3-852d-440e-9258-144106828597)
Revision Not Found for url: https://huggingface.co/OFA-Sys/small-stable-diffusion-v0/resolve/None/tokenizer/tokenizer_config.json.
Invalid rev id: None
The above exception was the direct cause of the following exception:
Traceback (most recent call last):
  File "E:\CV\Final_Test\FashioneDIFF\train.py", line 324, in <module>
    main()
  File "E:\CV\Final_Test\FashioneDIFF\train.py", line 118, in main
    model, tokenizer = load_models(config)
  File "E:\CV\Final_Test\FashioneDIFF\train.py", line 45, in load_models
    tokenizer = CLIPTokenizer.from_pretrained(
  File "C:\Users\nguye\AppData\Local\Programs\Python\Python310\lib\site-packages\transformers\tokenization_utils_base.py", line 1952, in from_pretrained
    resolved_config_file = cached_file(
  File "C:\Users\nguye\AppData\Local\Programs\Python\Python310\lib\site-packages\transformers\utils\hub.py", line 413, in cached_file
    raise EnvironmentError(
OSError: None is not a valid git identifier (branch name, tag name or commit id) that exists for this model name. Check the model page at 'https://huggingface.co/OFA-Sys/small-stable-diffusion-v0' for available revisions.